{"name": "test_login_failed_by_wrong_datas[data0]", "status": "passed", "attachments": [{"name": "log", "source": "4c4be8ed-2506-4a48-96ff-3935a0bc25bd-attachment.txt", "type": "text/plain"}], "parameters": [{"name": "data", "value": "{'user': '18600000000', 'passwd': 'pthon', 'check': '此账号没有经过授权，请联系管理员!'}"}], "start": 1561300544067, "stop": 1561300544791, "uuid": "bcd9c949-af54-46ea-bfea-46516ea3a831", "historyId": "32103ef82b089f5e07902f80d9a161fd", "fullName": "test_cases.test_login.TestLogin#test_login_failed_by_wrong_datas[data0]", "labels": [{"name": "tag", "value": "login"}, {"name": "parentSuite", "value": "test_cases"}, {"name": "suite", "value": "test_login"}, {"name": "subSuite", "value": "TestLogin"}, {"name": "host", "value": "PCOS-2014PXGVWP"}, {"name": "thread", "value": "5284-MainThread"}, {"name": "framework", "value": "pytest"}, {"name": "language", "value": "cpython3"}, {"name": "package", "value": "test_cases.test_login"}]}