{"name": "test_login_failed_by_wrong_datas[data0]", "status": "passed", "attachments": [{"name": "log", "source": "18dd083b-0afc-4828-83f9-dfac3fbd9d18-attachment.txt", "type": "text/plain"}], "parameters": [{"name": "data", "value": "{'user': '18600000000', 'passwd': 'pthon', 'check': '此账号没有经过授权，请联系管理员!'}"}], "start": 1561304447049, "stop": 1561304447717, "uuid": "001b4f52-a6ee-4dd1-a68c-1504bfe99ed8", "historyId": "32103ef82b089f5e07902f80d9a161fd", "fullName": "test_cases.test_login.TestLogin#test_login_failed_by_wrong_datas[data0]", "labels": [{"name": "tag", "value": "login"}, {"name": "parentSuite", "value": "test_cases"}, {"name": "suite", "value": "test_login"}, {"name": "subSuite", "value": "TestLogin"}, {"name": "host", "value": "PCOS-2014PXGVWP"}, {"name": "thread", "value": "11440-MainThread"}, {"name": "framework", "value": "pytest"}, {"name": "language", "value": "cpython3"}, {"name": "package", "value": "test_cases.test_login"}]}